--------------------------------------------------------------------------
KeyError                                  Traceback (most recent call last)
File ~\AppData\Local\anaconda3\lib\site-packages\pandas\core\indexes\base.py:3802, in Index.get_loc(self, key, method, tolerance)
   3801 try:
-> 3802     return self._engine.get_loc(casted_key)
   3803 except KeyError as err:

File ~\AppData\Local\anaconda3\lib\site-packages\pandas\_libs\index.pyx:138, in pandas._libs.index.IndexEngine.get_loc()

File ~\AppData\Local\anaconda3\lib\site-packages\pandas\_libs\index.pyx:165, in pandas._libs.index.IndexEngine.get_loc()

File pandas\_libs\hashtable_class_helper.pxi:5745, in pandas._libs.hashtable.PyObjectHashTable.get_item()

File pandas\_libs\hashtable_class_helper.pxi:5753, in pandas._libs.hashtable.PyObjectHashTable.get_item()

KeyError: 'Datetime'

The above exception was the direct cause of the following exception:

KeyError                                  Traceback (most recent call last)
Cell In[16], line 9
      6 df = pd.read_excel("G:\FP&A\PLANNING\Labor Project\Project - Demetris\Dataset 1.0.xlsx")
      8 # Convert 'Datetime' to datetime object
----> 9 df['Datetime'] = pd.to_datetime(df['Datetime'])
     11 # Set 'Datetime' as the index
     12 df.set_index('Datetime', inplace=True)

File ~\AppData\Local\anaconda3\lib\site-packages\pandas\core\frame.py:3807, in DataFrame.__getitem__(self, key)
   3805 if self.columns.nlevels > 1:
   3806     return self._getitem_multilevel(key)
-> 3807 indexer = self.columns.get_loc(key)
   3808 if is_integer(indexer):
   3809     indexer = [indexer]

File ~\AppData\Local\anaconda3\lib\site-packages\pandas\core\indexes\base.py:3804, in Index.get_loc(self, key, method, tolerance)
   3802     return self._engine.get_loc(casted_key)
   3803 except KeyError as err:
-> 3804     raise KeyError(key) from err
   3805 except TypeError:
   3806     # If we have a listlike key, _check_indexing_error will raise
   3807     #  InvalidIndexError. Otherwise we fall through and re-raise
   3808     #  the TypeError.
   3809     self._check_indexing_error(key)

KeyError: 'Datetime'
   1656         raise ValueError(
   1657             "Excel file format cannot be determined, you must specify "
   1658             "an engine manually."
   1659         )

File ~\AppData\Local\anaconda3\lib\site-packages\pandas\io\excel\_base.py:1525, in inspect_excel_format(content_or_path, storage_options)
   1522 if isinstance(content_or_path, bytes):
   1523     content_or_path = BytesIO(content_or_path)
-> 1525 with get_handle(
   1526     content_or_path, "rb", storage_options=storage_options, is_text=False
   1527 ) as handle:
   1528     stream = handle.handle
   1529     stream.seek(0)

File ~\AppData\Local\anaconda3\lib\site-packages\pandas\io\common.py:865, in get_handle(path_or_buf, mode, encoding, compression, memory_map, is_text, errors, storage_options)
    856         handle = open(
    857             handle,
    858             ioargs.mode,
   (...)
    861             newline="",
    862         )
    863     else:
    864         # Binary mode
--> 865         handle = open(handle, ioargs.mode)
    866     handles.append(handle)
    868 # Convert BytesIO or file objects passed with an encoding

FileNotFoundError: [Errno 2] No such file or directory: 'C:\\Users\\1001437\\Desktop\\Project Runaway\\Dataset 1.0 - Shortcut.xlsx'
